<?xml version="1.0" ?>
<robot name="spot">
    <link name="body">
        <visual>
            <origin rpy="1.570796 0 1.570796" xyz="0 0 0"/>
            <geometry>
                <mesh filename="package://spot_description/meshes/body.dae" />
            </geometry>
        </visual>
    </link>

    <link name="base_link"/>
    <joint name="base_link_joint" type="fixed">
        <origin xyz="0 0 0" rpy="0 0 0" />
        <parent link="body" />
        <child link="base_link" />
    </joint>

    <link name="front_rail"/>
    <joint name="front_rail_joint" type="fixed">
        <origin xyz="0.223 0 0.0805" rpy="0 0 0" />
        <parent link="body" />
        <child link="front_rail" />
    </joint>

    <link name="rear_rail"/>
    <joint name="rear_rail_joint" type="fixed">
        <origin xyz="-0.223 0 0.0805" rpy="0 0 0" />
        <parent link="body" />
        <child link="rear_rail" />
    </joint>

    <link name="front_left_hip">
        <visual>
            <origin rpy="1.570796 0 1.570796" xyz="0 0 0"/>
            <geometry>
                <mesh filename="package://spot_description/meshes/front_left_hip.dae" />
            </geometry>
        </visual>
    </link>
    <joint name="front_left_hip_x" type="revolute">
        <origin xyz="0.29785 0.05500 0.00000" rpy="0 0 0" />
        <axis xyz="1 0 0" />
        <parent link="body" />
        <child link="front_left_hip" />
        <limit effort="1000" velocity="1000.00" lower="-0.78539816339744827899" upper="0.78539816339744827899" />
    </joint>
    <link name="front_left_upper_leg">
        <visual>
            <origin rpy="0.785398 0 1.570796" xyz="0 0 0"/>
            <geometry>
                <mesh filename="package://spot_description/meshes/front_left_upper_leg.dae" />
            </geometry>
        </visual>
    </link>
    <joint name="front_left_hip_y" type="revolute">
        <origin xyz="0.0 0.110945 0.0" rpy="0 0 0" />
        <axis xyz="0 1 0" />
        <parent link="front_left_hip" />
        <child link="front_left_upper_leg" />
        <limit effort="1000" velocity="1000.00" lower="-0.89884456477707963539" upper="2.2951079663725435509" />
    </joint>
    <link name="front_left_lower_leg">
        <visual>
            <origin rpy="2.356194 0 1.570796" xyz="0 0 0"/>
            <geometry>
                <mesh filename="package://spot_description/meshes/front_left_lower_leg.dae" />
            </geometry>
        </visual>
    </link>
    <joint name="front_left_knee" type="revolute">
        <origin xyz="0.025 0.000 -0.3205" rpy="0 0 0" />
        <axis xyz="0 1 0" />
        <parent link="front_left_upper_leg" />
        <child link="front_left_lower_leg" />
        <limit effort="1000" velocity="1000.00" lower="-2.7929" upper="-0.254801" />
    </joint>
    <link name="front_right_hip">
        <visual>
            <origin rpy="1.570796 0 1.570796" xyz="0 0 0"/>
            <geometry>
                <mesh filename="package://spot_description/meshes/front_right_hip.dae" />
            </geometry>
        </visual>
    </link>
    <joint name="front_right_hip_x" type="revolute">
        <origin xyz="0.29785 -0.05500 0.00000" rpy="0 0 0" />
        <axis xyz="1 0 0" />
        <parent link="body" />
        <child link="front_right_hip" />
        <limit effort="1000" velocity="1000.00" lower="-0.78539816339744827899" upper="0.78539816339744827899" />
    </joint>
    <link name="front_right_upper_leg">
        <visual>
            <origin rpy="0.785398 0 1.570796" xyz="0 0 0"/>
            <geometry>
                <mesh filename="package://spot_description/meshes/front_right_upper_leg.dae" />
            </geometry>
        </visual>
    </link>
    <joint name="front_right_hip_y" type="revolute">
        <origin xyz="0.0 -0.110945 0.0" rpy="0 0 0" />
        <axis xyz="0 1 0" />
        <parent link="front_right_hip" />
        <child link="front_right_upper_leg" />
        <limit effort="1000" velocity="1000.00" lower="-0.89884456477707963539" upper="2.2951079663725435509" />
    </joint>
    <link name="front_right_lower_leg">
        <visual>
            <origin rpy="2.356194 0 1.570796" xyz="0 0 0"/>
            <geometry>
                <mesh filename="package://spot_description/meshes/front_right_lower_leg.dae" />
            </geometry>
        </visual>
    </link>
    <joint name="front_right_knee" type="revolute">
        <origin xyz="0.025 0.000 -0.3205" rpy="0 0 0" />
        <axis xyz="0 1 0" />
        <parent link="front_right_upper_leg" />
        <child link="front_right_lower_leg" />
        <limit effort="1000" velocity="1000.00" lower="-2.7929" upper="-0.247563" />
    </joint>
    <link name="rear_left_hip">
        <visual>
            <origin rpy="1.570796 0 1.570796" xyz="0 0 0"/>
            <geometry>
                <mesh filename="package://spot_description/meshes/rear_left_hip.dae" />
            </geometry>
        </visual>
    </link>
    <joint name="rear_left_hip_x" type="revolute">
        <origin xyz="-0.29785 0.05500 0.00000" rpy="0 0 0" />
        <axis xyz="1 0 0" />
        <parent link="body" />
        <child link="rear_left_hip" />
        <limit effort="1000" velocity="1000.00" lower="-0.78539816339744827899" upper="0.78539816339744827899" />
    </joint>
    <link name="rear_left_upper_leg">
        <visual>
            <origin rpy="0.88 0 1.570796" xyz="0 0 0"/>
            <geometry>
                <mesh filename="package://spot_description/meshes/rear_left_upper_leg.dae" />
            </geometry>
        </visual>
    </link>
    <joint name="rear_left_hip_y" type="revolute">
        <origin xyz="0.0 0.110945 0.0" rpy="0 0 0" />
        <axis xyz="0 1 0" />
        <parent link="rear_left_hip" />
        <child link="rear_left_upper_leg" />
        <limit effort="1000" velocity="1000.00" lower="-0.89884456477707963539" upper="2.2951079663725435509" />
    </joint>
    <link name="rear_left_lower_leg">
        <visual>
            <origin rpy="2.356194 0 1.570796" xyz="0 0 0"/>
            <geometry>
                <mesh filename="package://spot_description/meshes/rear_left_lower_leg.dae" />
            </geometry>
        </visual>
    </link>
    <joint name="rear_left_knee" type="revolute">
        <origin xyz="0.025 0.000 -0.3205" rpy="0 0 0" />
        <axis xyz="0 1 0" />
        <parent link="rear_left_upper_leg" />
        <child link="rear_left_lower_leg" />
        <limit effort="1000" velocity="1000.00" lower="-2.7929" upper="-0.267153" />
    </joint>
    <link name="rear_right_hip">
        <visual>
            <origin rpy="1.570796 0 1.570796" xyz="0 0 0"/>
            <geometry>
                <mesh filename="package://spot_description/meshes/rear_right_hip.dae" />
            </geometry>
        </visual>
    </link>
    <joint name="rear_right_hip_x" type="revolute">
        <origin xyz="-0.29785 -0.05500 0.00000" rpy="0 0 0" />
        <axis xyz="1 0 0" />
        <parent link="body" />
        <child link="rear_right_hip" />
        <limit effort="1000" velocity="1000.00" lower="-0.78539816339744827899" upper="0.78539816339744827899" />
    </joint>
    <link name="rear_right_upper_leg">
        <visual>
            <origin rpy="0.88 0 1.570796" xyz="0 0 0"/>
            <geometry>
                <mesh filename="package://spot_description/meshes/rear_right_upper_leg.dae" />
            </geometry>
        </visual>
    </link>
    <joint name="rear_right_hip_y" type="revolute">
        <origin xyz="0.0 -0.110945 0.0" rpy="0 0 0" />
        <axis xyz="0 1 0" />
        <parent link="rear_right_hip" />
        <child link="rear_right_upper_leg" />
        <limit effort="1000" velocity="1000.00" lower="-0.89884456477707963539" upper="2.2951079663725435509" />
    </joint>
    <link name="rear_right_lower_leg">
        <visual>
            <origin rpy="2.356194 0 1.570796" xyz="0 0 0"/>
            <geometry>
                <mesh filename="package://spot_description/meshes/rear_right_lower_leg.dae" />
            </geometry>
        </visual>
    </link>
    <joint name="rear_right_knee" type="revolute">
        <origin xyz="0.025 0.000 -0.3205" rpy="0 0 0" />
        <axis xyz="0 1 0" />
        <parent link="rear_right_upper_leg" />
        <child link="rear_right_lower_leg" />
        <limit effort="1000" velocity="1000.00" lower="-2.7929" upper="-0.257725" />
    </joint>
</robot>
